<?xml version="1.0"?>
<robot xmlns:xacro="http://www.ros.org/wiki/xacro" >
    <xacro:include filename="inertial_macros.xacro" />

    <material name="white">
        <color rgba="1 1 1 1" />
    </material>

    <material name="orange">
        <color rgba="1 0.3 0.1 1"/>
    </material>

    <material name="blue">
        <color rgba="0.2 0.2 1 1"/>
    </material>

    <material name="black">
        <color rgba="0 0 0 1"/>
    </material>

    <material name="red">
        <color rgba="1 0 0 1"/>
    </material>

    <!-- BASE LINK -->

    <link name="base_link">
    </link>
    <joint name="base_footprint_joint" type="fixed">
    <parent link="base_link"/>
    <child link="base_footprint"/>
    <origin xyz="0 0 0" rpy="0 0 0"/>
    </joint>

    <link name="base_footprint">   
    </link>

    <joint name="chassis_joint" type="fixed">
        <parent link="base_link"/>
        <child link="chassis"/>
        <origin xyz="0 0 0"/>
    </joint>    

    <link name="chassis">
        <visual>
            <origin xyz="0 0 0" rpy="0 0 0"/>
            <geometry>
                <mesh filename="file:///home/gram/final_project/dae/robot.dae" scale = "1 1 1"/>
            </geometry>
            <!-- <material name="white"/> -->
        </visual>
        <collision>
            <geometry>
                <mesh filename="file:///home/gram/final_project/dae/robot.dae" scale = "1 1 1"/>
            </geometry>
        </collision>
        <xacro:inertial_box mass="15" x="0.1" y="0.1" z="0.15">
            <origin xyz="0.15 0 0.5" rpy="0 0 0"/>
        </xacro:inertial_box>

    </link>
    <gazebo reference="chassis">
        <material>Gazebo/Red</material>
        <mu1 value="0.001"/>
        <mu2 value="0.001"/>
    </gazebo>

    <!-- RIGHT WHEEL BACK-->

    <joint name="rightBack_wheel_joint" type="continuous">
        <parent link="base_link"/>
        <child link="rightBack_wheel"/>
        <origin xyz="0.2250 -0.275 0.055" rpy="0 0 ${pi/2}"/>
        <axis xyz="1 0 0"/>
    </joint>

    <link name="rightBack_wheel">
        <visual>
            <geometry>
                <mesh filename="file:///home/gram/final_project/dae/wheel.dae" scale = "1 1 1"/>
            </geometry>
            <material name="blue"/>
        </visual>
        <collision>
            <geometry>
                <mesh filename="file:///home/gram/final_project/dae/wheel.dae" scale = "1 1 1"/>
            </geometry>
        </collision>
        <xacro:inertial_cylinder mass="0.2" length="0.12" radius="0.06">
            <origin xyz="0 0 0" rpy="0 0 ${pi/2}"/>
        </xacro:inertial_cylinder>
    </link> 

    <!-- LEFT WHEEL BACK -->

    <joint name="leftBack_wheel_joint" type="continuous">
        <parent link="base_link"/>
        <child link="leftBack_wheel"/>
        <origin xyz="0.2250 0.275 0.055" rpy="0 0 ${pi/2}"/>
        <axis xyz="1 0 0"/>
    </joint>

    <link name="leftBack_wheel">
        <visual>
            <geometry>
                <mesh filename="file:///home/gram/final_project/dae/wheel.dae" scale = "1 1 1"/>
            </geometry>
            <material name="blue"/>
        </visual>
        <collision>
            <geometry>
                <mesh filename="file:///home/gram/final_project/dae/wheel.dae" scale = "1 1 1"/>
            </geometry>
        </collision>
        <xacro:inertial_cylinder mass="0.2" length="0.12" radius="0.06">
            <origin xyz="0 0 0" rpy="0 0 ${pi/2}"/>
        </xacro:inertial_cylinder>
    </link>   

    <!-- RIGHT WHEEL FORWARD-->

    <joint name="rightForward_wheel_joint" type="continuous">
        <parent link="base_link"/>
        <child link="rightForward_wheel"/>
        <origin xyz="-0.225 -0.275 0.055" rpy="0 0 ${pi/2}"/>
 
        <axis xyz="1 0 0"/>
    </joint>

    <link name="rightForward_wheel">
        <visual>
            <geometry>
                <mesh filename="file:///home/gram/final_project/dae/wheel.dae" scale = "1 1 1"/>
            </geometry>
            <material name="blue"/>
        </visual>
        <collision>
            <geometry>
                <mesh filename="file:///home/gram/final_project/dae/wheel.dae" scale = "1 1 1"/>
            </geometry>
        </collision>
        <xacro:inertial_cylinder mass="0.2" length="0.12" radius="0.06">
            <origin xyz="0 0 0" rpy="0 0 ${pi/2}"/>
        </xacro:inertial_cylinder>
    </link>

    <!-- LEFT WHEEL FORWARD-->

    <joint name="leftForward_wheel_joint" type="continuous">
        <parent link="base_link"/>
        <child link="leftForward_wheel"/>
        <origin xyz="-0.225 0.275 0.055" rpy="0 0 ${pi/2}"/> 
        <axis xyz="1 0 0"/>
    </joint>
    
    <link name="leftForward_wheel">
        <visual>
            <geometry>
                <mesh filename="file:///home/gram/final_project/dae/wheel.dae" scale = "1 1 1"/>
            </geometry>
            <material name="blue"/>
        </visual>
        <collision>
            <geometry>
                <mesh filename="file:///home/gram/final_project/dae/wheel.dae" scale = "1 1 1"/>
            </geometry>
        </collision>
        <xacro:inertial_cylinder mass="0.25" length="0.12" radius="0.06">
           <origin xyz="0 0 0" rpy="0 0 ${pi/2}"/>
        </xacro:inertial_cylinder>
    </link> 


    <!-- Machine_arm -->
    <joint name="hand1" type="continuous">
        <parent link="chassis"/>
        <child link="arm1"/>
        <origin xyz="0.25 0 0.6" rpy="0 ${pi/2} 0"/> 
        <axis xyz="0 0 1"/>
        <limit effort="50" velocity="1" lower="-0.35" upper="2.3"/>
        <dynamics daping="1" friction="1"/>
    </joint>
    
    <link name="arm1">
        <visual>
            <geometry>
                <mesh filename="file:///home/gram/final_project/dae/newhand1.dae" scale = "1 1 1"/>
            </geometry>
            <material name="blue"/>
        </visual>
        <collision>
            <geometry>
                <mesh filename="file:///home/gram/final_project/dae/newhand1.dae" scale = "1 1 1"/>
            </geometry>
        </collision>
        <xacro:inertial_cylinder mass="0.25" length="0.12" radius="0.06">
           <origin xyz="0 0 0" rpy="0 ${pi/2} 0"/>
        </xacro:inertial_cylinder>
    </link>


    <!-- Machine_arm2 -->
    <joint name="hand2" type="continuous">
        <parent link="arm1"/>
        <child link="arm2"/>
        <origin xyz="0 0.41 0.01" rpy="0 0 0"/> 
        <axis xyz="1 0 0"/>
        <limit effort="50" velocity="1" lower="-0.35" upper="2.3"/>
        <dynamics daping="1" friction="1"/>
    </joint>
    
    <link name="arm2">
        <visual>
            <geometry>
                <mesh filename="file:///home/gram/final_project/dae/newhand2.dae" scale = "1 1 1"/>
            </geometry>
            <material name="blue"/>
        </visual>
        <collision>
            <geometry>
                <mesh filename="file:///home/gram/final_project/dae/newhand2.dae" scale = "1 1 1"/>
            </geometry>
        </collision>
        <xacro:inertial_cylinder mass="0.25" length="0.12" radius="0.06">
           <origin xyz="0 0 0 " rpy="0 0 0"/>
        </xacro:inertial_cylinder>
    </link>


    <!-- Machine_arm3 -->
    <joint name="hand3" type="continuous">
        <parent link="arm2"/>
        <child link="arm3"/>
        <origin xyz="-0.05 0 0.15" rpy="0 ${pi/2} 0"/> 
        <axis xyz="0 1 0"/>
        <limit effort="50" velocity="1" lower="-0.35" upper="2.3"/>
        <dynamics daping="1" friction="1"/>
    </joint>
    
    <link name="arm3">
        <visual>
            <geometry>
                <mesh filename="file:///home/gram/final_project/dae/newhand3.dae" scale = "1 1 1"/>
            </geometry>
            <material name="blue"/>
        </visual>
        <collision>
            <geometry>
                <mesh filename="file:///home/gram/final_project/dae/newhand3.dae" scale = "1 1 1"/>
            </geometry>
        </collision>
        <xacro:inertial_cylinder mass="0.25" length="0.12" radius="0.06">
           <origin xyz="0 0 0 " rpy="0 0 0"/>
        </xacro:inertial_cylinder>
    </link>


    <!-- Machine_arm4 -->
    <joint name="hand4" type="continuous">
        <parent link="arm2"/>
        <child link="arm4"/>
        <origin xyz="0.05 0 0.15" rpy="0 ${pi/2} 0"/> 
        <axis xyz="0 1 0"/>
        <limit effort="50" velocity="1" lower="-0.35" upper="2.3"/>
        <dynamics daping="1" friction="1"/>
    </joint>
    
    <link name="arm4">
        <visual>
            <geometry>
                <mesh filename="file:///home/gram/final_project/dae/newhand3.dae" scale = "1 1 1"/>
            </geometry>
            <material name="blue"/>
        </visual>
        <collision>
            <geometry>
                <mesh filename="file:///home/gram/final_project/dae/newhand3.dae" scale = "1 1 1"/>
            </geometry>
        </collision>
        <xacro:inertial_cylinder mass="0.25" length="0.12" radius="0.06">
           <origin xyz="0 0 0 " rpy="0 0 0"/>
        </xacro:inertial_cylinder>
    </link>

</robot>

